<?xml version='1.0' encoding='utf-8'?>
<robot name="hexapod">
  <material name="gray">
    <color rgba="0.7 0.7 0.7 1.0" />
  </material>
  <link name="base_link">
    <inertial>
      <origin xyz="0.0008471798785983058 0.004861289651277688 -0.008482185119927165" rpy="0 0 0" />
      <mass value="11.263155017509012" />
      <inertia ixx="0.253898" iyy="0.08278" izz="0.33649" ixy="0.0" iyz="0.0" ixz="0.0" />
    </inertial>
    <visual>
      <origin xyz="0 0 0" rpy="0 0 0" />
      <geometry>
        <mesh filename="../meshes/base_link.stl" scale="0.001 0.001 0.001" />
      </geometry>
      <material name="gray" />
    </visual>
    <collision>
      <origin xyz="0 0 0" rpy="0 0 0" />
      <geometry>
        <mesh filename="../meshes/base_link.stl" scale="0.001 0.001 0.001" />
      </geometry>
    </collision>
  </link>
  <link name="MR_coxa_1">
    <inertial>
      <origin xyz="-0.16134 0.051471 0.003482" rpy="0 0 0" />
      <mass value="0.2" />
      <inertia ixx="1.000000e-04" iyy="1.000000e-04" izz="1.000000e-04" ixy="0.0" iyz="0.0" ixz="0.0" />
    </inertial>
    <visual>
      <origin xyz="-0.16134 0.051471 0.003482" rpy="0 0 0" />
      <geometry>
        <mesh filename="../meshes/MR_coxa_1.stl" scale="0.001 0.001 0.001" />
      </geometry>
      <material name="gray" />
    </visual>
    <collision>
      <origin xyz="-0.16134 0.051471 0.003482" rpy="0 0 0" />
      <geometry>
        <mesh filename="../meshes/MR_coxa_1.stl" scale="0.001 0.001 0.001" />
      </geometry>
    </collision>
  </link>
  <link name="FR_coxa_1">
    <inertial>
      <origin xyz="-0.090847 -0.255486 0.003482" rpy="0 0 0" />
      <mass value="0.2" />
      <inertia ixx="1.000000e-04" iyy="1.000000e-04" izz="1.000000e-04" ixy="0.0" iyz="0.0" ixz="0.0" />
    </inertial>
    <visual>
      <origin xyz="-0.090847 -0.255486 0.003482" rpy="0 0 0" />
      <geometry>
        <mesh filename="../meshes/FR_coxa_1.stl" scale="0.001 0.001 0.001" />
      </geometry>
      <material name="gray" />
    </visual>
    <collision>
      <origin xyz="-0.090847 -0.255486 0.003482" rpy="0 0 0" />
      <geometry>
        <mesh filename="../meshes/FR_coxa_1.stl" scale="0.001 0.001 0.001" />
      </geometry>
    </collision>
  </link>
  <link name="BR_coxa_1">
    <inertial>
      <origin xyz="-0.080847 0.23279 0.003482" rpy="0 0 0" />
      <mass value="0.2" />
      <inertia ixx="1.000000e-04" iyy="1.000000e-04" izz="1.000000e-04" ixy="0.0" iyz="0.0" ixz="0.0" />
    </inertial>
    <visual>
      <origin xyz="-0.080847 0.23279 0.003482" rpy="0 0 0" />
      <geometry>
        <mesh filename="../meshes/BR_coxa_1.stl" scale="0.001 0.001 0.001" />
      </geometry>
      <material name="gray" />
    </visual>
    <collision>
      <origin xyz="-0.080847 0.23279 0.003482" rpy="0 0 0" />
      <geometry>
        <mesh filename="../meshes/BR_coxa_1.stl" scale="0.001 0.001 0.001" />
      </geometry>
    </collision>
  </link>
  <link name="FL_coxa_1">
    <inertial>
      <origin xyz="0.089153 -0.255486 0.003482" rpy="0 0 0" />
      <mass value="0.2" />
      <inertia ixx="1.000000e-04" iyy="1.000000e-04" izz="1.000000e-04" ixy="0.0" iyz="0.0" ixz="0.0" />
    </inertial>
    <visual>
      <origin xyz="0.089153 -0.255486 0.003482" rpy="0 0 0" />
      <geometry>
        <mesh filename="../meshes/FL_coxa_1.stl" scale="0.001 0.001 0.001" />
      </geometry>
      <material name="gray" />
    </visual>
    <collision>
      <origin xyz="0.089153 -0.255486 0.003482" rpy="0 0 0" />
      <geometry>
        <mesh filename="../meshes/FL_coxa_1.stl" scale="0.001 0.001 0.001" />
      </geometry>
    </collision>
  </link>
  <link name="FL_femur_1">
    <inertial>
      <origin xyz="-0.11029048242100645 0.035471989809574445 4.0271584568832286e-07" rpy="0 0 0" />
      <mass value="1.0" />
      <inertia ixx="1.000000e-03" iyy="1.000000e-03" izz="1.000000e-03" ixy="0.0" iyz="0.0" ixz="0.0" />
    </inertial>
    <visual>
      <origin xyz="0.146674 -0.315226 -0.029046" rpy="0 0 0" />
      <geometry>
        <mesh filename="../meshes/FL_femur_1.stl" scale="0.001 0.001 0.001" />
      </geometry>
      <material name="gray" />
    </visual>
    <collision>
      <origin xyz="0.146674 -0.315226 -0.029046" rpy="0 0 0" />
      <geometry>
        <mesh filename="../meshes/FL_femur_1.stl" scale="0.001 0.001 0.001" />
      </geometry>
    </collision>
  </link>
  <link name="BL_tibia_1">
    <inertial>
      <origin xyz="-0.24365603913458905 -0.1435076247203662 -0.04432699297836132" rpy="0 0 0" />
      <mass value="0.7" />
      <inertia ixx="7.000000e-04" iyy="7.000000e-04" izz="7.000000e-04" ixy="0.0" iyz="0.0" ixz="0.0" />
    </inertial>
    <visual>
      <origin xyz="0.344647 0.385059 -0.029047" rpy="0 0 0" />
      <geometry>
        <mesh filename="../meshes/BL_tibia_1.stl" scale="0.001 0.001 0.001" />
      </geometry>
      <material name="gray" />
    </visual>
    <collision>
      <origin xyz="0.344647 0.385059 -0.029047" rpy="0 0 0" />
      <geometry>
        <mesh filename="../meshes/BL_tibia_1.stl" scale="0.001 0.001 0.001" />
      </geometry>
    </collision>
  </link>
  <link name="ML_tibia_1">
    <inertial>
      <origin xyz="-0.2827662078365218 -0.0024526810045005995 -0.044326992978361374" rpy="0 0 0" />
      <mass value="0.7" />
      <inertia ixx="7.000000e-04" iyy="7.000000e-04" izz="7.000000e-04" ixy="0.0" iyz="0.0" ixz="0.0" />
    </inertial>
    <visual>
      <origin xyz="0.465705 0.050593 -0.029047" rpy="0 0 0" />
      <geometry>
        <mesh filename="../meshes/ML_tibia_1.stl" scale="0.001 0.001 0.001" />
      </geometry>
      <material name="gray" />
    </visual>
    <collision>
      <origin xyz="0.465705 0.050593 -0.029047" rpy="0 0 0" />
      <geometry>
        <mesh filename="../meshes/ML_tibia_1.stl" scale="0.001 0.001 0.001" />
      </geometry>
    </collision>
  </link>
  <link name="FL_tibia_1">
    <inertial>
      <origin xyz="-0.2573100817312584 0.11727917022203821 -0.044326992978362324" rpy="0 0 0" />
      <mass value="0.7" />
      <inertia ixx="7.000000e-04" iyy="7.000000e-04" izz="7.000000e-04" ixy="0.0" iyz="0.0" ixz="0.0" />
    </inertial>
    <visual>
      <origin xyz="0.366165 -0.385628 -0.029047" rpy="0 0 0" />
      <geometry>
        <mesh filename="../meshes/FL_tibia_1.stl" scale="0.001 0.001 0.001" />
      </geometry>
      <material name="gray" />
    </visual>
    <collision>
      <origin xyz="0.366165 -0.385628 -0.029047" rpy="0 0 0" />
      <geometry>
        <mesh filename="../meshes/FL_tibia_1.stl" scale="0.001 0.001 0.001" />
      </geometry>
    </collision>
  </link>
  <link name="ML_coxa_1">
    <inertial>
      <origin xyz="0.159646 0.051471 0.003482" rpy="0 0 0" />
      <mass value="0.2" />
      <inertia ixx="1.000000e-04" iyy="1.000000e-04" izz="1.000000e-04" ixy="0.0" iyz="0.0" ixz="0.0" />
    </inertial>
    <visual>
      <origin xyz="0.159646 0.051471 0.003482" rpy="0 0 0" />
      <geometry>
        <mesh filename="../meshes/ML_coxa_1.stl" scale="0.001 0.001 0.001" />
      </geometry>
      <material name="gray" />
    </visual>
    <collision>
      <origin xyz="0.159646 0.051471 0.003482" rpy="0 0 0" />
      <geometry>
        <mesh filename="../meshes/ML_coxa_1.stl" scale="0.001 0.001 0.001" />
      </geometry>
    </collision>
  </link>
  <link name="BL_coxa_1">
    <inertial>
      <origin xyz="0.079153 0.23279 0.003482" rpy="0 0 0" />
      <mass value="0.2" />
      <inertia ixx="1.000000e-04" iyy="1.000000e-04" izz="1.000000e-04" ixy="0.0" iyz="0.0" ixz="0.0" />
    </inertial>
    <visual>
      <origin xyz="0.079153 0.23279 0.003482" rpy="0 0 0" />
      <geometry>
        <mesh filename="../meshes/BL_coxa_1.stl" scale="0.001 0.001 0.001" />
      </geometry>
      <material name="gray" />
    </visual>
    <collision>
      <origin xyz="0.079153 0.23279 0.003482" rpy="0 0 0" />
      <geometry>
        <mesh filename="../meshes/BL_coxa_1.stl" scale="0.001 0.001 0.001" />
      </geometry>
    </collision>
  </link>
  <link name="ML_femur_1">
    <inertial>
      <origin xyz="-0.1149484184032751 -0.01446297408074099 4.0271584682630146e-07" rpy="0 0 0" />
      <mass value="1.0" />
      <inertia ixx="1.000000e-03" iyy="1.000000e-03" izz="1.000000e-03" ixy="0.0" iyz="0.0" ixz="0.0" />
    </inertial>
    <visual>
      <origin xyz="0.237025 0.021637 -0.029046" rpy="0 0 0" />
      <geometry>
        <mesh filename="../meshes/ML_femur_1.stl" scale="0.001 0.001 0.001" />
      </geometry>
      <material name="gray" />
    </visual>
    <collision>
      <origin xyz="0.237025 0.021637 -0.029046" rpy="0 0 0" />
      <geometry>
        <mesh filename="../meshes/ML_femur_1.stl" scale="0.001 0.001 0.001" />
      </geometry>
    </collision>
  </link>
  <link name="BL_femur_1">
    <inertial>
      <origin xyz="-0.09231673440290544 -0.06999931732268327 4.027158461185343e-07" rpy="0 0 0" />
      <mass value="1.0" />
      <inertia ixx="1.000000e-03" iyy="1.000000e-03" izz="1.000000e-03" ixy="0.0" iyz="0.0" ixz="0.0" />
    </inertial>
    <visual>
      <origin xyz="0.161082 0.245643 -0.029046" rpy="0 0 0" />
      <geometry>
        <mesh filename="../meshes/BL_femur_1.stl" scale="0.001 0.001 0.001" />
      </geometry>
      <material name="gray" />
    </visual>
    <collision>
      <origin xyz="0.161082 0.245643 -0.029046" rpy="0 0 0" />
      <geometry>
        <mesh filename="../meshes/BL_femur_1.stl" scale="0.001 0.001 0.001" />
      </geometry>
    </collision>
  </link>
  <link name="FR_femur_1">
    <inertial>
      <origin xyz="0.10920092283881766 0.03493074590276829 6.761700534901882e-08" rpy="0 0 0" />
      <mass value="1.0" />
      <inertia ixx="1.000000e-03" iyy="1.000000e-03" izz="1.000000e-03" ixy="0.0" iyz="0.0" ixz="0.0" />
    </inertial>
    <visual>
      <origin xyz="-0.148368 -0.315226 -0.029046" rpy="0 0 0" />
      <geometry>
        <mesh filename="../meshes/FR_femur_1.stl" scale="0.001 0.001 0.001" />
      </geometry>
      <material name="gray" />
    </visual>
    <collision>
      <origin xyz="-0.148368 -0.315226 -0.029046" rpy="0 0 0" />
      <geometry>
        <mesh filename="../meshes/FR_femur_1.stl" scale="0.001 0.001 0.001" />
      </geometry>
    </collision>
  </link>
  <link name="FR_tibia_1">
    <inertial>
      <origin xyz="0.2503203165467311 0.13134965047004704 -0.044326663176026085" rpy="0 0 0" />
      <mass value="0.7" />
      <inertia ixx="7.000000e-04" iyy="7.000000e-04" izz="7.000000e-04" ixy="0.0" iyz="0.0" ixz="0.0" />
    </inertial>
    <visual>
      <origin xyz="-0.367859 -0.385628 -0.029046" rpy="0 0 0" />
      <geometry>
        <mesh filename="../meshes/FR_tibia_1.stl" scale="0.001 0.001 0.001" />
      </geometry>
      <material name="gray" />
    </visual>
    <collision>
      <origin xyz="-0.367859 -0.385628 -0.029046" rpy="0 0 0" />
      <geometry>
        <mesh filename="../meshes/FR_tibia_1.stl" scale="0.001 0.001 0.001" />
      </geometry>
    </collision>
  </link>
  <link name="BR_femur_1">
    <inertial>
      <origin xyz="0.09124841811037479 -0.06941726541801047 6.761700563351347e-08" rpy="0 0 0" />
      <mass value="1.0" />
      <inertia ixx="1.000000e-03" iyy="1.000000e-03" izz="1.000000e-03" ixy="0.0" iyz="0.0" ixz="0.0" />
    </inertial>
    <visual>
      <origin xyz="-0.162776 0.245643 -0.029046" rpy="0 0 0" />
      <geometry>
        <mesh filename="../meshes/BR_femur_1.stl" scale="0.001 0.001 0.001" />
      </geometry>
      <material name="gray" />
    </visual>
    <collision>
      <origin xyz="-0.162776 0.245643 -0.029046" rpy="0 0 0" />
      <geometry>
        <mesh filename="../meshes/BR_femur_1.stl" scale="0.001 0.001 0.001" />
      </geometry>
    </collision>
  </link>
  <link name="BR_tibia_1">
    <inertial>
      <origin xyz="0.25117272765098597 -0.12971146666504613 -0.04432666317602593" rpy="0 0 0" />
      <mass value="0.7" />
      <inertia ixx="7.000000e-04" iyy="7.000000e-04" izz="7.000000e-04" ixy="0.0" iyz="0.0" ixz="0.0" />
    </inertial>
    <visual>
      <origin xyz="-0.346341 0.385059 -0.029046" rpy="0 0 0" />
      <geometry>
        <mesh filename="../meshes/BR_tibia_1.stl" scale="0.001 0.001 0.001" />
      </geometry>
      <material name="gray" />
    </visual>
    <collision>
      <origin xyz="-0.346341 0.385059 -0.029046" rpy="0 0 0" />
      <geometry>
        <mesh filename="../meshes/BR_tibia_1.stl" scale="0.001 0.001 0.001" />
      </geometry>
    </collision>
  </link>
  <link name="MR_femur_1">
    <inertial>
      <origin xyz="0.11373220040839996 -0.014493049317919764 6.761700591800812e-08" rpy="0 0 0" />
      <mass value="1.0" />
      <inertia ixx="1.000000e-03" iyy="1.000000e-03" izz="1.000000e-03" ixy="0.0" iyz="0.0" ixz="0.0" />
    </inertial>
    <visual>
      <origin xyz="-0.238719 0.021637 -0.029046" rpy="0 0 0" />
      <geometry>
        <mesh filename="../meshes/MR_femur_1.stl" scale="0.001 0.001 0.001" />
      </geometry>
      <material name="gray" />
    </visual>
    <collision>
      <origin xyz="-0.238719 0.021637 -0.029046" rpy="0 0 0" />
      <geometry>
        <mesh filename="../meshes/MR_femur_1.stl" scale="0.001 0.001 0.001" />
      </geometry>
    </collision>
  </link>
  <link name="MR_tibia_1">
    <inertial>
      <origin xyz="0.2823777690224717 0.013253497777558826 -0.044326663176026695" rpy="0 0 0" />
      <mass value="0.7" />
      <inertia ixx="7.000000e-04" iyy="7.000000e-04" izz="7.000000e-04" ixy="0.0" iyz="0.0" ixz="0.0" />
    </inertial>
    <visual>
      <origin xyz="-0.467399 0.050593 -0.029046" rpy="0 0 0" />
      <geometry>
        <mesh filename="../meshes/MR_tibia_1.stl" scale="0.001 0.001 0.001" />
      </geometry>
      <material name="gray" />
    </visual>
    <collision>
      <origin xyz="-0.467399 0.050593 -0.029046" rpy="0 0 0" />
      <geometry>
        <mesh filename="../meshes/MR_tibia_1.stl" scale="0.001 0.001 0.001" />
      </geometry>
    </collision>
  </link>
  <joint name="MR_coxa_joint" type="revolute">
    <origin xyz="0.16134 -0.051471 -0.003482" rpy="0 0 0" />
    <parent link="base_link" />
    <child link="MR_coxa_1" />
    <axis xyz="0.0 0.0 1.0" />
    <limit lower="-0.785398" upper="0.785398" effort="1000.0" velocity="100.0" />
    <dynamics damping="0.1" friction="0.01" />
  </joint>
  <joint name="FR_coxa_joint" type="revolute">
    <origin xyz="0.090847 0.255486 -0.003482" rpy="0 0 0" />
    <parent link="base_link" />
    <child link="FR_coxa_1" />
    <axis xyz="0.0 0.0 1.0" />
    <limit lower="-0.785398" upper="0.785398" effort="1000.0" velocity="100.0" />
    <dynamics damping="0.1" friction="0.01" />
  </joint>
  <joint name="BR_coxa_joint" type="revolute">
    <origin xyz="0.080847 -0.23279 -0.003482" rpy="0 0 0" />
    <parent link="base_link" />
    <child link="BR_coxa_1" />
    <axis xyz="0.0 0.0 1.0" />
    <limit lower="-0.785398" upper="0.785398" effort="1000.0" velocity="100.0" />
    <dynamics damping="0.1" friction="0.01" />
  </joint>
  <joint name="FL_coxa_joint" type="revolute">
    <origin xyz="-0.089153 0.255486 -0.003482" rpy="0 0 0" />
    <parent link="base_link" />
    <child link="FL_coxa_1" />
    <axis xyz="0.0 0.0 -1.0" />
    <limit lower="-0.785398" upper="0.785398" effort="1000.0" velocity="100.0" />
    <dynamics damping="0.1" friction="0.01" />
  </joint>
  <joint name="FL_femur_joint" type="revolute">
    <origin xyz="-0.057521 0.05974 0.032528" rpy="0 0 0" />
    <parent link="FL_coxa_1" />
    <child link="FL_femur_1" />
    <axis xyz="-0.4784 -0.8781 0.0" />
    <limit lower="-1.221730" upper="0.000000" effort="1000.0" velocity="100.0" />
    <dynamics damping="0.1" friction="0.01" />
  </joint>
  <joint name="BL_tibia_joint" type="revolute">
    <origin xyz="-0.183565 -0.139416 1e-06" rpy="0 0 0" />
    <parent link="BL_femur_1" />
    <child link="BL_tibia_1" />
    <axis xyz="0.4449 -0.8956 0.0" />
    <limit lower="0.000000" upper="2.443461" effort="1000.0" velocity="100.0" />
    <dynamics damping="0.1" friction="0.01" />
  </joint>
  <joint name="ML_tibia_joint" type="revolute">
    <origin xyz="-0.22868 -0.028956 1e-06" rpy="0 0 0" />
    <parent link="ML_femur_1" />
    <child link="ML_tibia_1" />
    <axis xyz="-0.0247 -0.9997 0.0" />
    <limit lower="0.000000" upper="2.443461" effort="1000.0" velocity="100.0" />
    <dynamics damping="0.1" friction="0.01" />
  </joint>
  <joint name="FL_tibia_joint" type="revolute">
    <origin xyz="-0.219491 0.070402 1e-06" rpy="0 0 0" />
    <parent link="FL_femur_1" />
    <child link="FL_tibia_1" />
    <axis xyz="-0.4784 -0.8781 0.0" />
    <limit lower="0.000000" upper="2.443461" effort="1000.0" velocity="100.0" />
    <dynamics damping="0.1" friction="0.01" />
  </joint>
  <joint name="ML_coxa_joint" type="revolute">
    <origin xyz="-0.159646 -0.051471 -0.003482" rpy="0 0 0" />
    <parent link="base_link" />
    <child link="ML_coxa_1" />
    <axis xyz="0.0 0.0 -1.0" />
    <limit lower="-0.785398" upper="0.785398" effort="1000.0" velocity="100.0" />
    <dynamics damping="0.1" friction="0.01" />
  </joint>
  <joint name="BL_coxa_joint" type="revolute">
    <origin xyz="-0.079153 -0.23279 -0.003482" rpy="0 0 0" />
    <parent link="base_link" />
    <child link="BL_coxa_1" />
    <axis xyz="0.0 0.0 -1.0" />
    <limit lower="-0.785398" upper="0.785398" effort="1000.0" velocity="100.0" />
    <dynamics damping="0.1" friction="0.01" />
  </joint>
  <joint name="ML_femur_joint" type="revolute">
    <origin xyz="-0.077379 0.029834 0.032528" rpy="0 0 0" />
    <parent link="ML_coxa_1" />
    <child link="ML_femur_1" />
    <axis xyz="-0.0247 -0.9997 0.0" />
    <limit lower="-1.221730" upper="0.000000" effort="1000.0" velocity="100.0" />
    <dynamics damping="0.1" friction="0.01" />
  </joint>
  <joint name="BL_femur_joint" type="revolute">
    <origin xyz="-0.081929 -0.012853 0.032528" rpy="0 0 0" />
    <parent link="BL_coxa_1" />
    <child link="BL_femur_1" />
    <axis xyz="0.4449 -0.8956 0.0" />
    <limit lower="-1.221730" upper="0.000000" effort="1000.0" velocity="100.0" />
    <dynamics damping="0.1" friction="0.01" />
  </joint>
  <joint name="FR_femur_joint" type="revolute">
    <origin xyz="0.057521 0.05974 0.032528" rpy="0 0 0" />
    <parent link="FR_coxa_1" />
    <child link="FR_femur_1" />
    <axis xyz="0.4784 -0.8781 0.0" />
    <limit lower="0.000000" upper="1.221730" effort="1000.0" velocity="100.0" />
    <dynamics damping="0.1" friction="0.01" />
  </joint>
  <joint name="FR_tibia_joint" type="revolute">
    <origin xyz="0.219491 0.070402 0.0" rpy="0 0 0" />
    <parent link="FR_femur_1" />
    <child link="FR_tibia_1" />
    <axis xyz="0.4784 -0.8781 0.0" />
    <limit lower="-2.443461" upper="0.000000" effort="1000.0" velocity="100.0" />
    <dynamics damping="0.1" friction="0.01" />
  </joint>
  <joint name="BR_femur_joint" type="revolute">
    <origin xyz="0.081929 -0.012853 0.032528" rpy="0 0 0" />
    <parent link="BR_coxa_1" />
    <child link="BR_femur_1" />
    <axis xyz="-0.4449 -0.8956 0.0" />
    <limit lower="0.000000" upper="1.221730" effort="1000.0" velocity="100.0" />
    <dynamics damping="0.1" friction="0.01" />
  </joint>
  <joint name="BR_tibia_joint" type="revolute">
    <origin xyz="0.183565 -0.139416 0.0" rpy="0 0 0" />
    <parent link="BR_femur_1" />
    <child link="BR_tibia_1" />
    <axis xyz="-0.4449 -0.8956 0.0" />
    <limit lower="-2.443461" upper="0.000000" effort="1000.0" velocity="100.0" />
    <dynamics damping="0.1" friction="0.01" />
  </joint>
  <joint name="MR_femur_joint" type="revolute">
    <origin xyz="0.077379 0.029834 0.032528" rpy="0 0 0" />
    <parent link="MR_coxa_1" />
    <child link="MR_femur_1" />
    <axis xyz="0.0247 -0.9997 0.0" />
    <limit lower="0.000000" upper="1.221730" effort="1000.0" velocity="100.0" />
    <dynamics damping="0.1" friction="0.01" />
  </joint>
  <joint name="MR_tibia_joint" type="revolute">
    <origin xyz="0.22868 -0.028956 0.0" rpy="0 0 0" />
    <parent link="MR_femur_1" />
    <child link="MR_tibia_1" />
    <axis xyz="0.0247 -0.9997 0.0" />
    <limit lower="-2.443461" upper="0.000000" effort="1000.0" velocity="100.0" />
    <dynamics damping="0.1" friction="0.01" />
  </joint>
</robot>
